<?xml version="1.0" encoding="utf-8"?>
<!-- This URDF was automatically created by SolidWorks to URDF Exporter! Originally created by Stephen Brawner (brawner@gmail.com)
     Commit Version: 1.6.0-4-g7f85cfe  Build Version: 1.6.7995.38578
     For more information, please see http://wiki.ros.org/sw_urdf_exporter -->
<robot
  name="bras_robot_description">
  <gazebo>
    <plugin
      filename="ignition-gazebo-scene-broadcaster-system"
      name="gz::sim::systems::SceneBroadcaster">
    </plugin>
    <plugin
      filename="ignition-gazebo-user-commands-system"
      name="gz::sim::systems::UserCommands">
    </plugin>


  </gazebo>
  <link
    name="base_link">
    <inertial>
      <origin
        xyz="-0.000112276518592858 -0.00164685561298875 0.157275504059166"
        rpy="0 0 0" />
      <mass
        value="1.43989797660554" />
      <inertia
        ixx="0.00421280903314899"
        ixy="1.14019025551688E-08"
        ixz="-4.86068292649284E-06"
        iyy="0.0050721814067531"
        iyz="-9.01666969995564E-06"
        izz="0.00144057563235913" />
    </inertial>
    <visual>
      <origin
        xyz="0 0 0"
        rpy="0 0 0" />
      <geometry>
        <mesh
          filename="package://bras_robot_description/meshes/base_link.STL" />
      </geometry>
      <material
        name="">
        <color
          rgba="0.792156862745098 0.819607843137255 0.933333333333333 1" />
      </material>
    </visual>
    <collision>
      <origin
        xyz="0 0 0"
        rpy="0 0 0" />
      <geometry>
        <mesh
          filename="package://bras_robot_description/meshes/base_link.STL" />
      </geometry>
    </collision>
  </link>
  <link
    name="link_1">
    <inertial>
      <origin
        xyz="-0.0069621925067659 -0.0320322801757545 0.12987143971843"
        rpy="0 0 0" />
      <mass
        value="1.16479488059674" />
      <inertia
        ixx="0.00291565077630925"
        ixy="-2.87085873451067E-05"
        ixz="0.000109359215036351"
        iyy="0.00297796370527482"
        iyz="0.000348089463476517"
        izz="0.00141409540604966" />
    </inertial>
    <visual>
      <origin
        xyz="0 0 0"
        rpy="0 0 0" />
      <geometry>
        <mesh
          filename="package://bras_robot_description/meshes/link_1.STL" />
      </geometry>
      <material
        name="">
        <color
          rgba="0.792156862745098 0.819607843137255 0.933333333333333 1" />
      </material>
    </visual>
    <collision>
      <origin
        xyz="0 0 0"
        rpy="0 0 0" />
      <geometry>
        <mesh
          filename="package://bras_robot_description/meshes/link_1.STL" />
      </geometry>
    </collision>
  </link>
  <joint
    name="joint_1"
    type="revolute">
    <origin
      xyz="0 0.0271 0.3"
      rpy="0 -1.5708 0" />
    <parent
      link="base_link" />
    <child
      link="link_1" />
    <axis
      xyz="0 1 0" />
    <limit
      lower="-1.57"
      upper="1.57"
      effort="1000"
      velocity="1000" />
  </joint>
  <link
    name="link_2">
    <inertial>
      <origin
        xyz="-0.0166960256115633 0.023946015970559 0.0087302468799948"
        rpy="0 0 0" />
      <mass
        value="3.97578414362685" />
      <inertia
        ixx="0.0035963729659092"
        ixy="0.000116333454562833"
        ixz="0.000648711972126287"
        iyy="0.00738064370674828"
        iyz="-3.59055439082542E-05"
        izz="0.00448469092077726" />
    </inertial>
    <visual>
      <origin
        xyz="0 0 0"
        rpy="0 0 0" />
      <geometry>
        <mesh
          filename="package://bras_robot_description/meshes/link_2.STL" />
      </geometry>
      <material
        name="">
        <color
          rgba="0.792156862745098 0.819607843137255 0.933333333333333 1" />
      </material>
    </visual>
    <collision>
      <origin
        xyz="0 0 0"
        rpy="0 0 0" />
      <geometry>
        <mesh
          filename="package://bras_robot_description/meshes/link_2.STL" />
      </geometry>
    </collision>
  </link>
  <joint
    name="joint_2"
    type="revolute">
    <origin
      xyz="-0.017125 -0.0546 0.30107"
      rpy="0 0 0" />
    <parent
      link="link_1" />
    <child
      link="link_2" />
    <axis
      xyz="0 1 0" />
    <limit
      lower="0"
      upper="1.57"
      effort="0"
      velocity="0" />
  </joint>
  <gazebo>
      <plugin
        filename="ignition-gazebo-joint-position-controller-system"
        name="gz::sim::systems::JointPositionController">
        <joint_name>joint_1</joint_name>
        <topic>motor_command</topic>
      </plugin>
  </gazebo>
    <gazebo>
        <plugin filename="ignition-gazebo-joint-state-publisher-system" name="ignition::gazebo::systems::JointStatePublisher">
            <topic>joint_states</topic>
        </plugin>
    </gazebo>
    <gazebo>
        <plugin filename="gz_ros2_control-system" name="gz_ros2_control::GazeboSimROS2ControlPlugin">
            <parameters>$(find bras_robot_description)/config/bras_robot_controllers.yaml</parameters>
            <ros>
                <remapping>/controller_manager/robot_description:=/robot_description</remapping>
            </ros>
        </plugin>
    </gazebo>

    <ros2_control name="RobotSystem" type="system">
        <hardware>
            <plugin>gz_ros2_control/GazeboSimSystem</plugin>
        </hardware>


        <joint name="joint_1">
            <command_interface name="position">
                <param name="min">-2.879793</param>
                <param name="max">2.879793</param>
            </command_interface>
            <state_interface name="position"/>
        </joint>
    </ros2_control>

</robot>
